[2024-10-13 16:36:11 +0000] [422394] [INFO] Starting gunicorn 23.0.0
[2024-10-13 16:36:11 +0000] [422394] [INFO] Listening at: http://0.0.0.0:8000 (422394)
[2024-10-13 16:36:11 +0000] [422394] [INFO] Using worker: sync
[2024-10-13 16:36:11 +0000] [422521] [INFO] Booting worker with pid: 422521
[2024-10-13 16:36:11 +0000] [422521] [ERROR] Exception in worker process
Traceback (most recent call last):
  File "/home/u556129284/.local/lib/python3.9/site-packages/gunicorn/arbiter.py", line 608, in spawn_worker
    worker.init_process()
  File "/home/u556129284/.local/lib/python3.9/site-packages/gunicorn/workers/base.py", line 135, in init_process
    self.load_wsgi()
  File "/home/u556129284/.local/lib/python3.9/site-packages/gunicorn/workers/base.py", line 147, in load_wsgi
    self.wsgi = self.app.wsgi()
  File "/home/u556129284/.local/lib/python3.9/site-packages/gunicorn/app/base.py", line 66, in wsgi
    self.callable = self.load()
  File "/home/u556129284/.local/lib/python3.9/site-packages/gunicorn/app/wsgiapp.py", line 57, in load
    return self.load_wsgiapp()
  File "/home/u556129284/.local/lib/python3.9/site-packages/gunicorn/app/wsgiapp.py", line 47, in load_wsgiapp
    return util.import_app(self.app_uri)
  File "/home/u556129284/.local/lib/python3.9/site-packages/gunicorn/util.py", line 370, in import_app
    mod = importlib.import_module(module)
  File "/usr/lib64/python3.9/importlib/__init__.py", line 127, in import_module
    return _bootstrap._gcd_import(name[level:], package, level)
  File "<frozen importlib._bootstrap>", line 1030, in _gcd_import
  File "<frozen importlib._bootstrap>", line 1007, in _find_and_load
  File "<frozen importlib._bootstrap>", line 972, in _find_and_load_unlocked
  File "<frozen importlib._bootstrap>", line 228, in _call_with_frames_removed
  File "<frozen importlib._bootstrap>", line 1030, in _gcd_import
  File "<frozen importlib._bootstrap>", line 1007, in _find_and_load
  File "<frozen importlib._bootstrap>", line 984, in _find_and_load_unlocked
ModuleNotFoundError: No module named 'resumerank'
[2024-10-13 16:36:11 +0000] [422521] [INFO] Worker exiting (pid: 422521)
[2024-10-13 16:36:11 +0000] [422394] [ERROR] Worker (pid:422521) exited with code 3
[2024-10-13 16:36:11 +0000] [422394] [ERROR] Shutting down: Master
[2024-10-13 16:36:11 +0000] [422394] [ERROR] Reason: Worker failed to boot.
[2024-10-13 17:16:52 +0000] [455415] [INFO] Starting gunicorn 23.0.0
[2024-10-13 17:16:52 +0000] [455415] [INFO] Listening at: http://0.0.0.0:5000 (455415)
[2024-10-13 17:16:52 +0000] [455415] [INFO] Using worker: sync
[2024-10-13 17:16:52 +0000] [455534] [INFO] Booting worker with pid: 455534
[2024-10-13 17:16:52 +0000] [455842] [INFO] Booting worker with pid: 455842
OpenBLAS blas_thread_init: pthread_create failed for thread 33 of 64: Resource temporarily unavailable
OpenBLAS blas_thread_init: RLIMIT_NPROC 2059193 current, 2059193 max
OpenBLAS blas_thread_init: pthread_create failed for thread 34 of 64: Resource temporarily unavailable
OpenBLAS blas_thread_init: RLIMIT_NPROC 2059193 current, 2059193 max
OpenBLAS blas_thread_init: pthread_create failed for thread 35 of 64: Resource temporarily unavailable
OpenBLAS blas_thread_init: RLIMIT_NPROC 2059193 current, 2059193 max
OpenBLAS blas_thread_init: pthread_create failed for thread 36 of 64: Resource temporarily unavailable
OpenBLAS blas_thread_init: RLIMIT_NPROC 2059193 current, 2059193 max
OpenBLAS blas_thread_init: pthread_create failed for thread 37 of 64: Resource temporarily unavailable
OpenBLAS blas_thread_init: RLIMIT_NPROC 2059193 current, 2059193 max
OpenBLAS blas_thread_init: pthread_create failed for thread 38 of 64: Resource temporarily unavailable
OpenBLAS blas_thread_init: RLIMIT_NPROC 2059193 current, 2059193 max
OpenBLAS blas_thread_init: pthread_create failed for thread 39 of 64: Resource temporarily unavailable
OpenBLAS blas_thread_init: RLIMIT_NPROC 2059193 current, 2059193 max
OpenBLAS blas_thread_init: pthread_create failed for thread 40 of 64: Resource temporarily unavailable
OpenBLAS blas_thread_init: RLIMIT_NPROC 2059193 current, 2059193 max
OpenBLAS blas_thread_init: pthread_create failed for thread 41 of 64: Resource temporarily unavailable
OpenBLAS blas_thread_init: RLIMIT_NPROC 2059193 current, 2059193 max
OpenBLAS blas_thread_init: pthread_create failed for thread 42 of 64: Resource temporarily unavailable
OpenBLAS blas_thread_init: RLIMIT_NPROC 2059193 current, 2059193 max
OpenBLAS blas_thread_init: pthread_create failed for thread 43 of 64: Resource temporarily unavailable
OpenBLAS blas_thread_init: RLIMIT_NPROC 2059193 current, 2059193 max
OpenBLAS blas_thread_init: pthread_create failed for thread 44 of 64: Resource temporarily unavailable
OpenBLAS blas_thread_init: RLIMIT_NPROC 2059193 current, 2059193 max
OpenBLAS blas_thread_init: pthread_create failed for thread 45 of 64: Resource temporarily unavailable
OpenBLAS blas_thread_init: RLIMIT_NPROC 2059193 current, 2059193 max
OpenBLAS blas_thread_init: pthread_create failed for thread 46 of 64: Resource temporarily unavailable
OpenBLAS blas_thread_init: RLIMIT_NPROC 2059193 current, 2059193 max
OpenBLAS blas_thread_init: pthread_create failed for thread 47 of 64: Resource temporarily unavailable
OpenBLAS blas_thread_init: RLIMIT_NPROC 2059193 current, 2059193 max
OpenBLAS blas_thread_init: pthread_create failed for thread 48 of 64: Resource temporarily unavailable
OpenBLAS blas_thread_init: RLIMIT_NPROC 2059193 current, 2059193 max
OpenBLAS blas_thread_init: pthread_create failed for thread 49 of 64: Resource temporarily unavailable
OpenBLAS blas_thread_init: RLIMIT_NPROC 2059193 current, 2059193 max
OpenBLAS blas_thread_init: pthread_create failed for thread 50 of 64: Resource temporarily unavailable
OpenBLAS blas_thread_init: RLIMIT_NPROC 2059193 current, 2059193 max
OpenBLAS blas_thread_init: pthread_create failed for thread 51 of 64: Resource temporarily unavailable
OpenBLAS blas_thread_init: RLIMIT_NPROC 2059193 current, 2059193 max
OpenBLAS blas_thread_init: pthread_create failed for thread 52 of 64: Resource temporarily unavailable
OpenBLAS blas_thread_init: RLIMIT_NPROC 2059193 current, 2059193 max
OpenBLAS blas_thread_init: pthread_create failed for thread 53 of 64: Resource temporarily unavailable
OpenBLAS blas_thread_init: RLIMIT_NPROC 2059193 current, 2059193 max
OpenBLAS blas_thread_init: pthread_create failed for thread 54 of 64: Resource temporarily unavailable
OpenBLAS blas_thread_init: RLIMIT_NPROC 2059193 current, 2059193 max
OpenBLAS blas_thread_init: pthread_create failed for thread 55 of 64: Resource temporarily unavailable
OpenBLAS blas_thread_init: RLIMIT_NPROC 2059193 current, 2059193 max
OpenBLAS blas_thread_init: pthread_create failed for thread 56 of 64: Resource temporarily unavailable
OpenBLAS blas_thread_init: RLIMIT_NPROC 2059193 current, 2059193 max
OpenBLAS blas_thread_init: pthread_create failed for thread 57 of 64: Resource temporarily unavailable
OpenBLAS blas_thread_init: RLIMIT_NPROC 2059193 current, 2059193 max
OpenBLAS blas_thread_init: pthread_create failed for thread 58 of 64: Resource temporarily unavailable
OpenBLAS blas_thread_init: RLIMIT_NPROC 2059193 current, 2059193 max
OpenBLAS blas_thread_init: pthread_create failed for thread 59 of 64: Resource temporarily unavailable
OpenBLAS blas_thread_init: RLIMIT_NPROC 2059193 current, 2059193 max
OpenBLAS blas_thread_init: pthread_create failed for thread 60 of 64: Resource temporarily unavailable
OpenBLAS blas_thread_init: RLIMIT_NPROC 2059193 current, 2059193 max
OpenBLAS blas_thread_init: pthread_create failed for thread 61 of 64: Resource temporarily unavailable
OpenBLAS blas_thread_init: RLIMIT_NPROC 2059193 current, 2059193 max
OpenBLAS blas_thread_init: pthread_create failed for thread 62 of 64: Resource temporarily unavailable
OpenBLAS blas_thread_init: RLIMIT_NPROC 2059193 current, 2059193 max
OpenBLAS blas_thread_init: pthread_create failed for thread 63 of 64: Resource temporarily unavailable
OpenBLAS blas_thread_init: RLIMIT_NPROC 2059193 current, 2059193 max
[2024-10-13 17:16:52 +0000] [455415] [ERROR] Unhandled exception in main loop
Traceback (most recent call last):
  File "/home/u556129284/.local/lib/python3.9/site-packages/gunicorn/arbiter.py", line 201, in run
    self.manage_workers()
  File "/home/u556129284/.local/lib/python3.9/site-packages/gunicorn/arbiter.py", line 570, in manage_workers
    self.spawn_workers()
  File "/home/u556129284/.local/lib/python3.9/site-packages/gunicorn/arbiter.py", line 641, in spawn_workers
    self.spawn_worker()
  File "/home/u556129284/.local/lib/python3.9/site-packages/gunicorn/arbiter.py", line 592, in spawn_worker
    pid = os.fork()
BlockingIOError: [Errno 11] Resource temporarily unavailable
[2024-10-13 17:16:52 +0000] [455842] [INFO] Worker exiting (pid: 455842)
[2024-10-13 17:16:52 +0000] [455534] [INFO] Worker exiting (pid: 455534)
[2024-10-13 17:16:52 +0000] [455415] [ERROR] Worker (pid:455842) was sent code 139!
[2024-10-13 17:19:57 +0000] [744498] [INFO] Starting gunicorn 23.0.0
[2024-10-13 17:19:57 +0000] [744498] [ERROR] Connection in use: ('0.0.0.0', 8080)
[2024-10-13 17:19:57 +0000] [744498] [ERROR] connection to ('0.0.0.0', 8080) failed: [Errno 98] Address already in use
[2024-10-13 17:19:58 +0000] [744498] [ERROR] Connection in use: ('0.0.0.0', 8080)
[2024-10-13 17:19:58 +0000] [744498] [ERROR] connection to ('0.0.0.0', 8080) failed: [Errno 98] Address already in use
[2024-10-13 17:19:59 +0000] [744498] [ERROR] Connection in use: ('0.0.0.0', 8080)
[2024-10-13 17:19:59 +0000] [744498] [ERROR] connection to ('0.0.0.0', 8080) failed: [Errno 98] Address already in use
[2024-10-13 17:20:00 +0000] [744498] [ERROR] Connection in use: ('0.0.0.0', 8080)
[2024-10-13 17:20:00 +0000] [744498] [ERROR] connection to ('0.0.0.0', 8080) failed: [Errno 98] Address already in use
[2024-10-13 17:20:01 +0000] [744498] [ERROR] Connection in use: ('0.0.0.0', 8080)
[2024-10-13 17:20:01 +0000] [744498] [ERROR] connection to ('0.0.0.0', 8080) failed: [Errno 98] Address already in use
[2024-10-13 17:20:02 +0000] [744498] [ERROR] Can't connect to ('0.0.0.0', 8080)
[2024-10-13 18:05:33 +0000] [1096111] [INFO] Starting gunicorn 23.0.0
[2024-10-13 18:05:33 +0000] [1096111] [ERROR] Connection in use: ('0.0.0.0', 5000)
[2024-10-13 18:05:33 +0000] [1096111] [ERROR] connection to ('0.0.0.0', 5000) failed: [Errno 98] Address already in use
[2024-10-13 18:05:34 +0000] [1096111] [ERROR] Connection in use: ('0.0.0.0', 5000)
[2024-10-13 18:05:34 +0000] [1096111] [ERROR] connection to ('0.0.0.0', 5000) failed: [Errno 98] Address already in use
[2024-10-13 18:05:35 +0000] [1096111] [ERROR] Connection in use: ('0.0.0.0', 5000)
[2024-10-13 18:05:35 +0000] [1096111] [ERROR] connection to ('0.0.0.0', 5000) failed: [Errno 98] Address already in use
[2024-10-13 18:05:36 +0000] [1096111] [ERROR] Connection in use: ('0.0.0.0', 5000)
[2024-10-13 18:05:36 +0000] [1096111] [ERROR] connection to ('0.0.0.0', 5000) failed: [Errno 98] Address already in use
[2024-10-13 18:05:37 +0000] [1096111] [ERROR] Connection in use: ('0.0.0.0', 5000)
[2024-10-13 18:05:37 +0000] [1096111] [ERROR] connection to ('0.0.0.0', 5000) failed: [Errno 98] Address already in use
[2024-10-13 18:05:38 +0000] [1096111] [ERROR] Can't connect to ('0.0.0.0', 5000)
[2024-10-13 18:07:48 +0000] [1296436] [INFO] Starting gunicorn 23.0.0
[2024-10-13 18:07:48 +0000] [1296436] [ERROR] Connection in use: ('0.0.0.0', 5000)
[2024-10-13 18:07:48 +0000] [1296436] [ERROR] connection to ('0.0.0.0', 5000) failed: [Errno 98] Address already in use
[2024-10-13 18:07:49 +0000] [1296436] [ERROR] Connection in use: ('0.0.0.0', 5000)
[2024-10-13 18:07:49 +0000] [1296436] [ERROR] connection to ('0.0.0.0', 5000) failed: [Errno 98] Address already in use
[2024-10-13 18:07:50 +0000] [1296436] [ERROR] Connection in use: ('0.0.0.0', 5000)
[2024-10-13 18:07:50 +0000] [1296436] [ERROR] connection to ('0.0.0.0', 5000) failed: [Errno 98] Address already in use
[2024-10-13 18:07:51 +0000] [1296436] [ERROR] Connection in use: ('0.0.0.0', 5000)
[2024-10-13 18:07:51 +0000] [1296436] [ERROR] connection to ('0.0.0.0', 5000) failed: [Errno 98] Address already in use
[2024-10-13 18:07:52 +0000] [1296436] [ERROR] Connection in use: ('0.0.0.0', 5000)
[2024-10-13 18:07:52 +0000] [1296436] [ERROR] connection to ('0.0.0.0', 5000) failed: [Errno 98] Address already in use
[2024-10-13 18:07:53 +0000] [1296436] [ERROR] Can't connect to ('0.0.0.0', 5000)
[2024-10-13 18:10:52 +0000] [1625915] [INFO] Starting gunicorn 23.0.0
[2024-10-13 18:10:52 +0000] [1625915] [ERROR] Connection in use: ('0.0.0.0', 5000)
[2024-10-13 18:10:52 +0000] [1625915] [ERROR] connection to ('0.0.0.0', 5000) failed: [Errno 98] Address already in use
[2024-10-13 18:10:53 +0000] [1625915] [ERROR] Connection in use: ('0.0.0.0', 5000)
[2024-10-13 18:10:53 +0000] [1625915] [ERROR] connection to ('0.0.0.0', 5000) failed: [Errno 98] Address already in use
[2024-10-13 18:10:54 +0000] [1625915] [ERROR] Connection in use: ('0.0.0.0', 5000)
[2024-10-13 18:10:54 +0000] [1625915] [ERROR] connection to ('0.0.0.0', 5000) failed: [Errno 98] Address already in use
[2024-10-13 18:10:55 +0000] [1625915] [ERROR] Connection in use: ('0.0.0.0', 5000)
[2024-10-13 18:10:55 +0000] [1625915] [ERROR] connection to ('0.0.0.0', 5000) failed: [Errno 98] Address already in use
[2024-10-13 18:10:56 +0000] [1625915] [ERROR] Connection in use: ('0.0.0.0', 5000)
[2024-10-13 18:10:56 +0000] [1625915] [ERROR] connection to ('0.0.0.0', 5000) failed: [Errno 98] Address already in use
[2024-10-13 18:10:57 +0000] [1625915] [ERROR] Can't connect to ('0.0.0.0', 5000)
